Workbook

Sheet Lies mich
A1: Gag-Katalog Durchsicht – Wimmel Wizard
A2: Stand 25.10.2026. Quelle: public/js/pipeline.js (GAG_LIBRARY, GROUP_LIBRARY, HERO_ACTION_LIBRARY).
A4: So gehst du vor
A5: 1. Blätter „Gags“, „Gruppen“ und „Helden-Aktionen“: In der gelben Spalte „Entscheidung“ je Zeile Behalten / Streichen / Ändern wählen (Dropdown).
A6: 2. Bei „Ändern“ in „Deine Notiz“ kurz schreiben, was anders soll. Bei Streichen reicht das Wort.
A7: 3. Spalte „Hinweis“ ist meine Vorab-Durchsicht: Dubletten, Wiederholungsmuster, amerikanisch geprägte Einträge. Rot hinterlegt = Hinweis vorhanden.
A8: 4. Blatt „Neue Vorschläge“: 54 neue Situationen, europäisch und bewusst andere Typen (Zärtlich, Arbeit, Absurd). Auch dort Entscheidung wählen.
A9: 5. Blatt „Muster“ zeigt die Verteilung der Typen und zählt deine Entscheidungen live mit.
A11: Beispiel
A12: G159 | Berge | Ein Hund apportiert einen viel zu großen Stock | Entscheidung: Streichen | Notiz: Dublette zu G053
A14: Danach: Datei zurück an mich. Daraus entsteht der Situationen-Katalog für die Collage (Vorlage + Rollen + Tags) als Cowork-Auftrag.

Sheet Gags
A1: ID | B1: Thema | C1: Ebene | D1: Situation (DE) | E1: Prompt-Baustein (EN) | F1: Typ | G1: Hinweis aus der Durchsicht | H1: Entscheidung | I1: Deine Notiz
A2: G001 | B2: Zuhause | D2: Papa steckt beim Möbelaufbau fest und braucht Hilfe von allen | E2: dad stuck while assembling furniture, everyone pitching in to help | F2: Missgeschick | G2: Zuhause-Pool hat nur 10 Einträge – für die Collage zu dünn
A3: G002 | B3: Zuhause | D3: Die Katze hat sich in der Wäscheleine verheddert | E3: a cat tangled up in the laundry line | F3: Tier
A4: G003 | B4: Zuhause | D4: Ein Kuchen brennt fast an, weil alle beim Fernsehen zugesehen haben | E4: a cake almost burning while everyone was watching TV | F4: Missgeschick | G4: Zuhause-Pool hat nur 10 Einträge – für die Collage zu dünn
A5: G004 | B5: Zuhause | D5: Die Kinder bauen eine riesige Höhle aus Sofakissen | E5: kids building a huge fort out of sofa cushions | F5: Spiel/Bewegung
A6: G005 | B6: Zuhause | D6: Jemand sucht verzweifelt die zweite Socke | E6: someone desperately searching for a missing sock | F6: Alltag
A7: G006 | B7: Zuhause | D7: Ein Wasserrohrbruch verwandelt die Küche in einen kleinen See | E7: a burst pipe turning the kitchen into a small lake | F7: Alltag | G7: Zuhause-Pool hat nur 10 Einträge – für die Collage zu dünn
A8: G007 | B8: Zuhause | D8: Oma erzählt eine Geschichte und alle hören gebannt zu | E8: grandma telling a story while everyone listens spellbound | F8: Zusammen/Zärtlich
A9: G008 | B9: Zuhause | D9: Der Hund hat die Hausschuhe im ganzen Haus verteilt | E9: a dog scattering house slippers all over the house | F9: Tier
A10: G009 | B10: Zuhause | D10: Beim Frühstück fällt die Milch um und alle lachen | E10: spilled milk at breakfast with everyone laughing | F10: Missgeschick | G10: Milch/Flüssigkeit kippt 4×
A11: G010 | B11: Zuhause | D11: Im Kinderzimmer tobt eine Kissenschlacht | E11: a pillow fight raging in the kids' room | F11: Spiel/Bewegung
A12: G011 | B12: Strand | D12: Eine Sandburg wird von der Flut weggespült, alle rennen sie zu retten | E12: a sandcastle being washed away by the tide, everyone rushing to save it | F12: Missgeschick | G12: Sandburg 4× (G011, G028, G035, H009)
A13: G012 | B13: Strand | D13: Eine Möwe klaut jemandem die Pommes | E13: a seagull stealing someone's bag of fries | F13: Tier | G13: Muster „Tier klaut Essen/Gegenstand“ 5× (G012, G041, G101, G196, G222)
A14: G013 | B14: Strand | D14: Ein Drachen verheddert sich in einem Sonnenschirm | E14: a kite tangled up in a beach umbrella | F14: Missgeschick | G14: Drachen 4× im Katalog (G013, G042, G065, H014)
A15: G014 | B15: Strand | D15: Jemand wird beim Eincremen von einer Windböe überrascht | E15: a gust of wind surprising someone mid-sunscreen | F15: Missgeschick
A16: G015 | B16: Strand | D16: Ein Krebs kneift jemanden in den Zeh | E16: a crab pinching someone's toe, everyone startled | F16: Tier
A17: G016 | B17: Strand | D17: Ein aufblasbares Einhorn treibt langsam aufs Meer hinaus | E17: an inflatable unicorn drifting slowly out to sea | F17: Alltag
A18: G017 | B18: Strand | D18: Kinder buddeln einen Tunnel und treffen sich in der Mitte | E18: kids digging a tunnel and meeting in the middle | F18: Spiel/Bewegung
A19: G018 | B19: Strand | D19: Ein Hund buddelt ein riesiges Loch und wird ganz sandig | E19: a dog digging a huge sandy hole, covered in sand | F19: Tier
A20: G019 | B20: Strand | D20: Beim Beachvolleyball fliegt der Ball ins Wasser | E20: a beach volleyball flying into the water | F20: Missgeschick | G20: eher US-Strandbild (Beachvolleyball) – Alternative: Federball, Boule, Frisbee
A21: G020 | B21: Strand | D21: Jemand döst ein und wird fast von der Flut erwischt | E21: someone dozing off almost getting caught by the tide | F21: Missgeschick
A22: G021 | B22: Strand | D22: Ein Sonnenschirm klappt zusammen und begräbt ein Handtuch | E22: a beach umbrella collapsing onto a towel | F22: Missgeschick
A23: G022 | B23: Strand | D23: Jemand schleppt eine riesige Luftmatratze zum Wasser | E23: someone hauling a huge air mattress to the water | F23: Alltag | G23: Luftmatratze 2×
A24: G023 | B24: Strand | D24: Zwei Kinder sammeln Muscheln in einen Eimer und vergleichen sie | E24: two kids collecting shells in a bucket and comparing them | F24: Alltag
A25: G024 | B25: Strand | D25: Ein Kind steht bis zu den Knien im Wasser und zeigt auf einen Fisch | E25: a child knee-deep in the water pointing at a fish | F25: Tier
A26: G025 | B26: Strand | D26: Ein Handtuch wird vom Wind über den Strand getragen | E26: a towel carried across the beach by the wind | F26: Zusammen/Zärtlich
A27: G026 | B27: Strand | D27: Jemand gräbt eine Grube und verschwindet fast darin | E27: someone digging a pit and almost disappearing into it | F27: Missgeschick
A28: G027 | B28: Strand | D28: Ein Tretboot wird zu Wasser gelassen, alle schieben | E28: a pedal boat being launched with everyone pushing | F28: Alltag | G28: Tretboot 2×
A29: G028 | B29: Strand | D29: Eine Sandburg bekommt einen Wassergraben aus zwei Eimern | E29: a sandcastle getting a moat from two buckets | F29: Spiel/Bewegung | G29: Sandburg 4× (G011, G028, G035, H009)
A30: G029 | B30: Strand | D30: Ein Kind zieht einen Bollerwagen voller Strandzeug | E30: a child pulling a handcart full of beach gear | F30: Alltag | G30: Bollerwagen 3× (G029, G062, H023)
A31: G030 | B31: Strand | D31: Jemand ist komplett mit Sand bedeckt, nur der Kopf schaut heraus | E31: someone buried in sand with only their head showing | F31: Alltag
A32: G031 | B32: Strand | D32: Zwei Möwen zanken sich um ein Stück Brot | E32: two seagulls squabbling over a piece of bread | F32: Tier
A33: G032 | B33: Strand | D33: Jemand balanciert auf einem Stein am Wasserrand | E33: someone balancing on a stone at the water's edge | F33: Spiel/Bewegung
A34: G033 | B34: Strand | D34: Ein Schlauchboot treibt mit einem Hund darin am Ufer | E34: a rubber dinghy drifting near the shore with a dog in it | F34: Tier
A35: G034 | B35: Strand | D35: Ein Kind trägt einen Turm aus drei Eimern | E35: a child carrying a tower of three buckets | F35: Alltag
A36: G035 | B36: Strand | D36: Eine Welle erwischt eine Reihe aufgestellter Sandburgen | E36: a wave catching a row of sandcastles | F36: Missgeschick | G36: Sandburg 4× (G011, G028, G035, H009)
A37: G036 | B37: Strand | D37: Jemand wringt ein tropfnasses Handtuch aus | E37: someone wringing out a dripping towel | F37: Missgeschick
A38: G037 | B38: Strand | D38: Ein Junge übt Rad schlagen im flachen Wasser | E38: a boy practising cartwheels in the shallow water | F38: Spiel/Bewegung
A39: G038 | B39: Strand | D39: Ein Eisverkäufer wird von einer Traube Kinder umringt | E39: an ice cream seller surrounded by a cluster of children | F39: Arbeit/Alltag | G39: Eis 9× im Katalog – stärkster Wiederholer
A40: G039 | B40: Strand | D40: Ein Kind sammelt Treibholz zu einem Stapel | E40: a child collecting driftwood into a pile | F40: Alltag
...

Sheet Gruppen
A1: ID | B1: Thema | C1: Ebene | D1: Situation (DE) | E1: Prompt-Baustein (EN) | F1: Typ | G1: Hinweis aus der Durchsicht | H1: Entscheidung | I1: Deine Notiz
A2: GR001 | B2: Bauernhof | C2: Mitte | D2: Eine Schlange am Hofladen, mindestens acht Leute hintereinander | E2: a queue at the little farm shop, at least eight people standing one behind the other | F2: Alltag | G2: Warteschlange/Warten: 10 von 52 Gruppen – Hauptgrund für „sieht gleich aus“
A3: GR002 | B3: Bauernhof | C3: Mitte | D3: Eine Kindergruppe klettert gemeinsam ueber die Strohballen | E3: a group of about ten children clambering over a stack of straw bales together | F3: Spiel/Bewegung
A4: GR003 | B4: Bauernhof | C4: Mitte | D4: Eine fuenfkoepfige Familie beim Picknick in der Obstwiese | E4: a family of five spread out on a picnic blanket in the orchard | F4: Zusammen/Zärtlich
A5: GR004 | B5: Bauernhof | C5: hinten | D5: Zuschauer am Koppelzaun, acht oder neun nebeneinander | E5: a row of spectators leaning on the paddock fence, eight or nine of them side by side | F5: Alltag
A6: GR005 | B6: Bauernhof | C6: hinten | D6: Ein Erntetrupp von acht Leuten in der Apfelbaumreihe, teils auf Leitern | E6: a harvest crew of eight working along a row of apple trees, some up ladders, some carrying crates | F6: Arbeit/Alltag
A7: GR006 | B7: Bauernhof | C7: Mitte | D7: Eine lange Tafel im Hof, ein Dutzend Leute sitzt und isst | E7: a long table out in the yard with a dozen people sitting along it, eating together | F7: Alltag
A8: GR007 | B8: Bauernhof | C8: hinten | D8: Acht Leute draengen sich um einen Traktor, den jemand vorfuehrt | E8: a cluster of about eight people crowding around a tractor that someone is showing off | F8: Alltag
A9: GR008 | B9: Bauernhof | C9: hinten | D9: Eine Schulklasse von zwoelf Kindern wird in loser Reihe ueber den Hof gefuehrt | E9: a school class of twelve children being led across the yard in a straggly line | F9: Alltag
A10: GR009 | B10: Weihnachten | C10: Mitte | D10: Ein Chor von etwa zehn Leuten singt gemeinsam an der Tuer | E10: a choir of about ten people singing together by the door | F10: Alltag
A11: GR010 | B11: Weihnachten | C11: Mitte | D11: Eine achtkoepfige Familie draengt sich um den Esstisch | E11: a family of eight squeezed around the dinner table, plates and glasses everywhere | F11: Alltag
A12: GR011 | B12: Weihnachten | C12: Mitte | D12: Acht Kinder warten in einer Reihe, bis sie ihr Geschenk bekommen | E12: a queue of eight children waiting their turn at the presents | F12: Alltag | G12: Warteschlange/Warten: 10 von 52 Gruppen – Hauptgrund für „sieht gleich aus“
A13: GR012 | B13: Weihnachten | C13: hinten | D13: Neun Verwandte draengen sich gleichzeitig in den Flur, Maentel halb aus | E13: a knot of about nine relatives crowded into the hallway, coats half off, all arriving at once | F13: Alltag
A14: GR013 | B14: Weihnachten | C14: hinten | D14: Zehn Sternsinger mit Laternen vor dem Fenster | E14: a group of ten carol singers with lanterns outside the window | F14: Alltag
A15: GR014 | B15: Weihnachten | C15: Mitte | D15: Ein Dutzend Leute auf und um ein einziges Sofa vor dem Baum | E15: a dozen people packed onto and around one single sofa in front of the tree | F15: Alltag
A16: GR015 | B16: Weihnachten | C16: hinten | D16: Acht Leute stehen in der Kuechentuer und wollen alle gleichzeitig helfen | E16: a cluster of eight people in the kitchen doorway, all trying to help at once | F16: Alltag
A17: GR016 | B17: Weihnachten | C17: hinten | D17: Neun Kinder sitzen in einer Reihe auf der Treppe und schauen zu | E17: a row of nine children sitting on the stairs watching the grown-ups | F17: Zusammen/Zärtlich | G17: Treppe/Geländer 3×
A18: GR017 | B18: Strand | C18: Mitte | D18: Eine Schlange von zehn Leuten am Eisstand | E18: a queue of about ten people at the ice cream stand | F18: Alltag | G18: Eis 9× im Katalog – stärkster Wiederholer; Warteschlange/Warten: 10 von 52 Gruppen – Hauptgrund für „sieht gleich aus“
A19: GR018 | B19: Strand | C19: hinten | D19: Ein Volleyballspiel mit zwoelf Spielern und einem Ring Zuschauer | E19: a volleyball game with twelve players and a ring of onlookers around it | F19: Spiel/Bewegung | G19: eher US-Strandbild (Beachvolleyball) – Alternative: Federball, Boule, Frisbee
A20: GR019 | B20: Strand | C20: Mitte | D20: Eine sechskoepfige Familie unter einem viel zu kleinen Sonnenschirm | E20: a family of six crowded under one far too small parasol | F20: Missgeschick
A21: GR020 | B21: Strand | C21: hinten | D21: Ein Schwimmkurs, ein Dutzend Kinder in einer Reihe im flachen Wasser | E21: a swimming lesson with a dozen children lined up in the shallows | F21: Alltag
A22: GR021 | B22: Strand | C22: Mitte | D22: Acht Sonnenbadende dicht nebeneinander im Sand | E22: a row of eight sunbathers packed side by side on the sand | F22: Alltag
A23: GR022 | B23: Strand | C23: hinten | D23: Neun Leute draengen sich um ein Tretboot, das den Strand hochgezogen wird | E23: a cluster of about nine people crowded around a pedalo being dragged up the beach | F23: Alltag | G23: Tretboot 2×
A24: GR023 | B24: Strand | C24: Mitte | D24: Zehn Kinder graben gemeinsam ein riesiges Loch | E24: a group of ten children digging one enormous hole together | F24: Spiel/Bewegung
A25: GR024 | B25: Strand | C25: hinten | D25: Zwoelf Leute warten am Strandkiosk | E25: a line of twelve people waiting at the beach kiosk | F25: Alltag | G25: Warteschlange/Warten: 10 von 52 Gruppen – Hauptgrund für „sieht gleich aus“
A26: GR025 | B26: Berge | C26: Mitte | D26: Eine Schlange von zehn Wanderern an der Bergbahn | E26: a queue of about ten walkers at the cable car station | F26: Alltag | G26: Warteschlange/Warten: 10 von 52 Gruppen – Hauptgrund für „sieht gleich aus“
A27: GR026 | B27: Berge | C27: Mitte | D27: Ein Dutzend Leute an den langen Tischen der Huettenterrasse | E27: a dozen people packed onto the terrace of the mountain hut, all at long tables | F27: Alltag
A28: GR027 | B28: Berge | C28: hinten | D28: Eine Wandergruppe von neun Leuten im Gaensemarsch auf dem Pfad | E28: a hiking group of nine strung out along the path in single file | F28: Alltag | G28: Gänsemarsch 3×
A29: GR028 | B29: Berge | C29: hinten | D29: Eine Schulgruppe von zwoelf Kindern mit Fuehrer am Aussichtspunkt | E29: a school group of twelve children with a guide at a viewpoint | F29: Alltag
A30: GR029 | B30: Berge | C30: Mitte | D30: Acht Leute stehen um einen Wegweiser und zeigen in verschiedene Richtungen | E30: a cluster of eight people crowded around a signpost, all pointing in different directions | F30: Alltag
A31: GR030 | B31: Berge | C31: hinten | D31: Zehn Leute warten am Sessellift | E31: a queue of ten people waiting at the chairlift | F31: Alltag | G31: Warteschlange/Warten: 10 von 52 Gruppen – Hauptgrund für „sieht gleich aus“
A32: GR031 | B32: Berge | C32: Mitte | D32: Eine sechskoepfige Familie rastet gemeinsam auf einer Bank mit Aussicht | E32: a family of six resting together on a bench with a view | F32: Alltag
A33: GR032 | B33: Berge | C33: hinten | D33: Neun Leute sammeln sich um das Gipfelkreuz | E33: a group of about nine people gathered around a summit cross | F33: Alltag
A34: GR033 | B34: Stadt/Markt | C34: Mitte | D34: Eine Schlange von einem Dutzend Leuten an einem Marktstand | E34: a queue of a dozen people at a market stall | F34: Alltag | G34: Warteschlange/Warten: 10 von 52 Gruppen – Hauptgrund für „sieht gleich aus“
A35: GR034 | B35: Stadt/Markt | C35: hinten | D35: Etwa fuenfzehn Leute warten an der Tramhaltestelle | E35: a crowd of about fifteen people waiting at the tram stop | F35: Alltag | G35: Warteschlange/Warten: 10 von 52 Gruppen – Hauptgrund für „sieht gleich aus“
A36: GR035 | B36: Stadt/Markt | C36: Mitte | D36: Zehn Leute ueberqueren gleichzeitig den Zebrastreifen | E36: a group of ten people packed onto a zebra crossing, all crossing at once | F36: Tier
A37: GR036 | B37: Stadt/Markt | C37: Mitte | D37: Ein Strassencafe mit einem Dutzend Leuten an den Aussentischen | E37: a pavement cafe with a dozen people at the outside tables | F37: Alltag
A38: GR037 | B38: Stadt/Markt | C38: hinten | D38: Ein Ring von zehn Zuschauern um einen Strassenmusiker | E38: a ring of about ten onlookers around a street musician | F38: Alltag
A39: GR038 | B39: Stadt/Markt | C39: hinten | D39: Eine Schulklasse von zwoelf Kindern geht zu zweit den Gehweg entlang | E39: a school class of twelve children walking along the pavement two by two | F39: Alltag
A40: GR039 | B40: Stadt/Markt | C40: Mitte | D40: Neun Leute draengen sich um einen Zeitungskiosk | E40: a cluster of nine people crowded around a newspaper kiosk | F40: Alltag
...

Sheet Helden-Aktionen
A1: ID | B1: Thema | C1: Ebene | D1: Situation (DE) | E1: Prompt-Baustein (EN) | F1: Typ | G1: Hinweis aus der Durchsicht | H1: Entscheidung | I1: Deine Notiz
A2: H001 | B2: Bauernhof | D2: füttert ein Lamm aus der Flasche | E2: feeding a lamb from a bottle | F2: Tier | G2: Lamm aus der Flasche 2×
A3: H002 | B3: Bauernhof | D3: trägt einen Eimer Futter mit beiden Händen | E3: carrying a bucket of feed with both hands | F3: Alltag
A4: H003 | B4: Bauernhof | D4: klettert auf einen Strohballen | E4: climbing onto a straw bale | F4: Spiel/Bewegung
A5: H004 | B5: Bauernhof | D5: streichelt ein Kalb über die Stirn | E5: stroking a calf on the forehead | F5: Tier
A6: H005 | B6: Bauernhof | D6: sitzt auf dem Zaun und schaut über den Hof | E6: sitting on the fence looking across the yard | F6: Alltag | G6: Zaun 2×
A7: H006 | B7: Bauernhof | D7: hält ein Huhn im Arm | E7: holding a chicken in their arms | F7: Tier
A8: H007 | B8: Bauernhof | D8: schiebt eine Schubkarre voller Äpfel | E8: pushing a wheelbarrow full of apples | F8: Alltag | G8: Schubkarre 3×
A9: H008 | B9: Bauernhof | D9: sammelt Eier in einen Korb | E9: gathering eggs into a basket | F9: Alltag
A10: H009 | B10: Strand | D10: gräbt den Graben um eine Sandburg | E10: digging the moat around a sandcastle | F10: Spiel/Bewegung | G10: Sandburg 4× (G011, G028, G035, H009)
A11: H010 | B11: Strand | D11: hält ein Holzboot ins Wasser | E11: holding a wooden boat into the water | F11: Alltag
A12: H011 | B12: Strand | D12: springt über eine auslaufende Welle | E12: jumping over a running-out wave | F12: Spiel/Bewegung
A13: H012 | B13: Strand | D13: trägt zwei Eimer Wasser | E13: carrying two buckets of water | F13: Alltag
A14: H013 | B14: Strand | D14: sucht Muscheln im Spülsaum | E14: searching for shells along the waterline | F14: Alltag
A15: H014 | B15: Strand | D15: hält einen Drachen an der Schnur | E15: holding a kite by its string | F15: Spiel/Bewegung | G15: Drachen 4× im Katalog (G013, G042, G065, H014)
A16: H015 | B16: Strand | D16: steht bis zu den Knien im Wasser und schaut hinunter | E16: standing knee-deep in the water looking down | F16: Alltag
A17: H016 | B17: Strand | D17: schaufelt Sand über die Füße von jemandem | E17: shovelling sand over someone's feet | F17: Alltag
A18: H017 | B18: Park/Spielplatz | D18: schaukelt im Stehen | E18: swinging while standing up | F18: Spiel/Bewegung
A19: H018 | B19: Park/Spielplatz | D19: klettert die Leiter zur Rutsche hoch | E19: climbing the ladder to the slide | F19: Spiel/Bewegung
A20: H019 | B20: Park/Spielplatz | D20: hält einen Ball unter dem Arm | E20: holding a ball under one arm | F20: Spiel/Bewegung
A21: H020 | B21: Park/Spielplatz | D21: malt mit Kreide auf den Weg | E21: drawing on the path with chalk | F21: Spiel/Bewegung | G21: Kreide 2× (Gag + Helden-Aktion)
A22: H021 | B22: Park/Spielplatz | D22: füttert Enten am Teich | E22: feeding ducks at the pond | F22: Tier
A23: H022 | B23: Park/Spielplatz | D23: hängt am Klettergerüst | E23: hanging from the climbing frame | F23: Spiel/Bewegung
A24: H023 | B24: Park/Spielplatz | D24: zieht einen Bollerwagen hinter sich her | E24: pulling a handcart along behind them | F24: Alltag | G24: Bollerwagen 3× (G029, G062, H023)
A25: H024 | B25: Park/Spielplatz | D25: pustet Seifenblasen | E25: blowing soap bubbles | F25: Spiel/Bewegung | G25: Seifenblasen 2× (Gag + Helden-Aktion)
A26: H025 | B26: Stadt/Markt | D26: zeigt auf ein Schaufenster | E26: pointing at a shop window | F26: Alltag
A27: H026 | B27: Stadt/Markt | D27: hält eine Tüte Obst vom Markt | E27: holding a bag of fruit from the market | F27: Alltag
A28: H027 | B28: Stadt/Markt | D28: steht an der Eisdiele in der Schlange | E28: standing in the queue at the ice cream parlour | F28: Alltag | G28: Eis 9× im Katalog – stärkster Wiederholer
A29: H028 | B29: Stadt/Markt | D29: sitzt auf Schultern und schaut über die Menge | E29: sitting on someone's shoulders looking over the crowd | F29: Zusammen/Zärtlich | G29: Kind auf Schultern 2× (Gag + Helden-Aktion)
A30: H029 | B30: Stadt/Markt | D30: schiebt einen Roller neben sich | E30: pushing a scooter along beside them | F30: Alltag
A31: H030 | B31: Stadt/Markt | D31: zählt Münzen in der Hand | E31: counting coins in their hand | F31: Alltag
A32: H031 | B32: Stadt/Markt | D32: trägt ein langes Brot unter dem Arm | E32: carrying a long loaf under one arm | F32: Alltag
A33: H032 | B33: Stadt/Markt | D33: bleibt vor einem Straßenmusiker stehen | E33: stopping in front of a street musician | F33: Alltag
A34: H033 | B34: Berge | D34: trinkt aus der Feldflasche | E34: drinking from a water bottle | F34: Alltag
A35: H034 | B35: Berge | D35: klettert über einen Felsblock | E35: climbing over a boulder | F35: Spiel/Bewegung
A36: H035 | B36: Berge | D36: sammelt Steine in die Jackentasche | E36: collecting stones into a jacket pocket | F36: Alltag | G36: Steine sammeln 2×
A37: H036 | B37: Berge | D37: zeigt ins Tal hinunter | E37: pointing down into the valley | F37: Alltag
A38: H037 | B38: Berge | D38: stapft im Gänsemarsch voran | E38: trudging ahead in single file | F38: Alltag | G38: Gänsemarsch 3×
A39: H038 | B39: Berge | D39: hält einen Wanderstock in der Hand | E39: holding a hiking pole | F39: Zusammen/Zärtlich
A40: H039 | B40: Berge | D40: sitzt auf dem Rucksack und bindet den Schuh | E40: sitting on a backpack tying a shoe | F40: Arbeit/Alltag
...

Sheet Neue Vorschläge
A1: ID | B1: Thema | C1: Typ | D1: Situation (DE) | E1: Entscheidung | F1: Deine Notiz
A2: N001 | B2: Überall | C2: Zusammen/Zärtlich | D2: Ein Opa zeigt einem Kind, wie man eine Kastanie aufknackt
A3: N002 | B3: Überall | C3: Alltag | D3: Zwei Nachbarinnen reden über den Gartenzaun, beide mit Gießkanne in der Hand
A4: N003 | B4: Überall | C4: Arbeit/Alltag | D4: Ein Schornsteinfeger winkt vom Dach, unten winkt ein Kind zurück
A5: N004 | B5: Überall | C5: Zusammen/Zärtlich | D5: Ein Kind bekommt vom Bäcker eine Brezel über die Theke gereicht
A6: N005 | B6: Überall | C6: Arbeit/Alltag | D6: Papa pumpt einen Fahrradreifen auf, das Kind hält den Lenker fest
A7: N006 | B7: Überall | C7: Missgeschick | D7: Zwei teilen sich einen Regenschirm, einer wird trotzdem komplett nass
A8: N007 | B8: Überall | C8: Zusammen/Zärtlich | D8: Ein Kind schläft im Fahrradanhänger, Papa tritt kräftig in die Pedale
A9: N008 | B9: Überall | C9: Tier | D9: Oma strickt auf der Bank, der Wollknäuel rollt weg, die Katze hinterher
A10: N009 | B10: Überall | C10: Tier | D10: Der Postbote mit gelbem Fahrrad bringt ein Paket, der Hund freut sich mehr als die Familie
A11: N010 | B11: Überall | C11: Spiel/Bewegung | D11: Drei Kinder spielen Gummitwist
A12: N011 | B12: Überall | C12: Zusammen/Zärtlich | D12: Ein Kind zeigt stolz allen seinen Wackelzahn
A13: N012 | B13: Überall | C13: Missgeschick | D13: Ein Mann trägt eine Kiste Leergut zum Container, eine Flasche kullert davon
... A55: N054 | B55: Wald/Herbst (neu) | C55: Alltag | D55: Zwei Kinder klettern auf den Hochsitz, der Förster winkt sie herunter
A57: Running Gags (Vorschlag, je Buch 1–2 davon auf jeder Seite als Suchspiel):
A58: R01 | D58: Die Oma mit dem roten Regenschirm – bei jedem Wetter
A59: R02 | D59: Der Mann, dem auf jeder Seite der Hut wegfliegt – jedes Mal woanders
A60: R03 | D60: Dieselbe Katze auf einem anderen Dach
A61: R04 | D61: WizzelWim selbst, klein und gut versteckt

Sheet Muster
A1: Typ-Verteilung heute (Gags, 244 Einträge)
A2: Typ | B2: Anzahl | C2: Anteil
A3: Missgeschick | B3: =COUNTIF(Gags!$F$2:$F$245,A3) -> 56 | C3: =B3/244 -> 0.2295082
A4: Tier | B4: =COUNTIF(Gags!$F$2:$F$245,A4) -> 66 | C4: =B4/244 -> 0.2704918
A5: Spiel/Bewegung | B5: =COUNTIF(Gags!$F$2:$F$245,A5) -> 31 | C5: =B5/244 -> 0.12704918
A6: Arbeit/Alltag | B6: =COUNTIF(Gags!$F$2:$F$245,A6) -> 14 | C6: =B6/244 -> 0.057377049
A7: Zusammen/Zärtlich | B7: =COUNTIF(Gags!$F$2:$F$245,A7) -> 15 | C7: =B7/244 -> 0.06147541
A8: Alltag | B8: =COUNTIF(Gags!$F$2:$F$245,A8) -> 62 | C8: =B8/244 -> 0.25409836
A9: Typ wurde automatisch per Stichwort zugeordnet (grob, zur Orientierung).
A11: Deine Entscheidungen (live gezählt)
A12: Blatt | B12: Behalten | C12: Streichen | D12: Ändern | E12: offen
A13: Gags | B13: =COUNTIF(Gags!$H$2:$H$245,"Behalten") -> 0 | C13: =COUNTIF(Gags!$H$2:$H$245,"Streichen") -> 0 | D13: =COUNTIF(Gags!$H$2:$H$245,"Ändern") -> 0 | E13: =244-SUM(B13:D13) -> 244
A14: Gruppen | B14: =COUNTIF(Gruppen!$H$2:$H$53,"Behalten") -> 0 | C14: =COUNTIF(Gruppen!$H$2:$H$53,"Streichen") -> 0 | D14: =COUNTIF(Gruppen!$H$2:$H$53,"Ändern") -> 0 | E14: =52-SUM(B14:D14) -> 52
A15: Helden-Aktionen | B15: =COUNTIF('Helden-Aktionen'!$H$2:$H$57,"Behalten") -> 0 | C15: =COUNTIF('Helden-Aktionen'!$H$2:$H$57,"Streichen") -> 0 | D15: =COUNTIF('Helden-Aktionen'!$H$2:$H$57,"Ändern") -> 0 | E15: =56-SUM(B15:D15) -> 56
A16: Neue Vorschläge | B16: =COUNTIF('Neue Vorschläge'!$E$2:$E$55,"Behalten") -> 0 | C16: =COUNTIF('Neue Vorschläge'!$E$2:$E$55,"Streichen") -> 0 | D16: =COUNTIF('Neue Vorschläge'!$E$2:$E$55,"Ändern") -> 0 | E16: =54-SUM(B16:D16) -> 54
A19: Befunde der Durchsicht
A20: 1. Die Bibliothek ist schon weitgehend europäisch (Brotzeit, Almhütte, Sternsinger, Bollerwagen, Nikolausstiefel). Nur 3–5 Einträge sind klar amerikanisch geprägt. Der „amerikanische“ Eindruck der Bilder kommt also vor allem aus dem Hintergrund (Häuser, Straßen, Fahrzeuge), den das Modell von sich aus zeichnet – das gehört in den Szenen-Prompt, nicht in den Gag-Katalog.
A21: 2. Rund die Hälfte aller Gags ist ein Missgeschick oder ein Tier-Gag (etwas fällt, kippt, entwischt, ein Tier klaut etwas); Zärtliches und Arbeit/Handwerk zusammen nur etwa 12 %. Das erzeugt den Eindruck von Wiederholung, auch wenn die Situationen verschieden sind. Für mehr Varianz braucht der Katalog mehr Zärtliches, Arbeit/Handwerk und Absurdes.
A22: 3. Stärkste Wiederholer: Eis (9×), Warteschlange (10 von 52 Gruppen), Tier klaut Essen (5×), Sandburg (4×), Drachen (4×), Flüssigkeit kippt (4×).
A23: 4. Vier Themen haben nur 10 Einträge (Zuhause, Zoo, Schwimmbad, Kita/Schule). Für die Collage braucht jedes Thema mindestens 40 Situationen plus etwa 100 „Überall“-Situationen (heute 24).
A24: 5. Es fehlen typisch deutsche Orte: Badesee, Wochenmarkt (eigenständig), Volksfest/Kirmes, Wald/Herbst, Winter ohne Weihnachten, Garten/Schrebergarten, Bahnhof, Kindergeburtstag.
A25: 6. Viele Helden-Aktionen sind Kopien von Gags (Kreide, Seifenblasen, Schultern, Lamm, Schubkarre …). Im Collage-Modell übernehmen die erzählten Situationen der Kundin diese Rolle; die Helden-Aktionen werden nur noch als Rückfall gebraucht.
